Workbook

Sheet Master Data
A1: 📊 MASTER DATA — 비용 파라미터 (수정 시 전 시트 자동 반영)
A2: ⚠️ 🟡노란색=직접입력 | 🔵파란색=자동계산 | ⬜빈칸=신규항목 추가용
A3: 새 코스·호텔 추가는 빈칸에 직접 입력 → 자동으로 드롭다운에 반영
A5: ⛳ GOLF COURSES (1인 1라운드, USD)
A6: Course | B6: Cost ($) | C6: Sell ($) | D6: Margin ($) | E6: Notes
A7: Trump National LA | B7: 210 | C7: 500 | D7: =IF(A7="","",C7-B7) | E7: Member guest | Cart incl.
A8: Sandpiper GC | B8: 130 | C8: 245 | D8: =IF(A8="","",C8-B8) | E8: UnderPar deal | Replay free | Non-Resident
A9: Hidden Valley GC | B9: 109 | C9: 109 | D9: =IF(A9="","",C9-B9) | E9: teeitup.com | 9Stamps=1free
D10: =IF(A10="","",C10-B10)
D11: =IF(A11="","",C11-B11)
D12: =IF(A12="","",C12-B12)
D13: =IF(A13="","",C13-B13)
D14: =IF(A14="","",C14-B14)
A16: 🏨 HOTEL (1인 1박, Double Occupancy, USD)
A17: Hotel | B17: Cost/night | C17: Sell/night | D17: Margin | E17: Notes
A18: Beverly Wilshire (5★) / Same Tier | B18: 275 | C18: 375 | D18: =IF(A18="","",C18-B18) | E18: $550/room ÷ 2 persons
D19: =IF(A19="","",C19-B19)
D20: =IF(A20="","",C20-B20)
D21: =IF(A21="","",C21-B21)
D22: =IF(A22="","",C22-B22)
D23: =IF(A23="","",C23-B23)
A25: 🚐 TRANSPORT (1인 기준, 4인 1조, USD)
A26: Item | B26: Cost/p | C26: Sell/p | D26: Margin | E26: Notes
A27: Driver/Guide + Van (일당) | B27: 125 | C27: 175 | D27: =IF(A27="","",C27-B27) | E27: $500/day ÷ 4p | Driver=Guide
A28: Airport Roundtrip Pickup | B28: 75 | C28: 120 | D28: =IF(A28="","",C28-B28) | E28: LAX ↔ Hotel, per person
D29: =IF(A29="","",C29-B29)
D30: =IF(A30="","",C30-B30)
D31: =IF(A31="","",C31-B31)
D32: =IF(A32="","",C32-B32)
D33: =IF(A33="","",C33-B33)
A35: 🍽️ MEALS (1인 1끼, USD)
A36: Meal | B36: Cost | C36: Sell | D36: Margin | E36: Notes
A37: Breakfast (Hotel) | B37: 30 | C37: 45 | D37: =IF(A37="","",C37-B37) | E37: Daily included
A38: Lunch | B38: 40 | C38: 60 | D38: =IF(A38="","",C38-B38) | E38: Daily included
A39: Dinner (Regular) | B39: 80 | C39: 120 | D39: =IF(A39="","",C39-B39) | E39: Regular dinner
A40: Exclusive Dinner (Michelin/Fine) | B40: 120 | C40: 180 | D40: =IF(A40="","",C40-B40) | E40: 2x per trip
D41: =IF(A41="","",C41-B41)
D42: =IF(A42="","",C42-B42)
D43: =IF(A43="","",C43-B43)
D44: =IF(A44="","",C44-B44)
...

Sheet Package Types
A1: 🎯 결 TOUR — 대표 패키지 (1인 기준, USD | 중복코스 없음)
A2: ⚠️ 아래는 참고용 대표패키지 → 'Package Selector' 시트에서 자유롭게 커스터마이징 가능
A4: No | B4: ID | C4: 일정 | D4: 패키지명 | E4: 박 | F4: 일 | G4: Rds | H4: 코스구성 | I4: 골프C | J4: 골프S | K4: 호텔C | L4: 호텔S | M4: 마진 | N4: 마진율
A5: 1 | B5: S1 | C5: 3N4D | D5: 트럼프 + 샌드파이퍼 오션뷰 | E5: 3 | F5: 4 | G5: 2 | H5: Trump×1 + Sand×1 | I5: 340 | J5: 745 | K5: 825 | L5: 1125 | M5: 705 | N5: =IF(J5+L5>0,(J5+L5-I5-K5)/(J5+L5),0)
A6: 2 | B6: S2 | C6: 3N4D | D6: 트럼프 + 히든밸리 밸리뷰 | E6: 3 | F6: 4 | G6: 2 | H6: Trump×1 + HV×1 | I6: 319 | J6: 609 | K6: 825 | L6: 1125 | M6: =J6+L6-I6-K6 | N6: =IF(J6+L6>0,(J6+L6-I6-K6)/(J6+L6),0)
A7: 3 | B7: S3 | C7: 3N4D | D7: 샌드파이퍼 + 히든밸리 | E7: 3 | F7: 4 | G7: 2 | H7: Sand×1 + HV×1 | I7: 239 | J7: 354 | K7: 825 | L7: 1125 | M7: =J7+L7-I7-K7 | N7: =IF(J7+L7>0,(J7+L7-I7-K7)/(J7+L7),0)
A9: 4 | B9: M1 | C9: 5N7D | D9: 트럼프+샌드+히든 3色 시그니처 | E9: 5 | F9: 7 | G9: 3 | H9: Trump×1+Sand×1+HV×1 | I9: 449 | J9: 854 | K9: 1375 | L9: 1875 | M9: =J9+L9-I9-K9 | N9: =IF(J9+L9>0,(J9+L9-I9-K9)/(J9+L9),0)

Sheet Package Selector
A1: 🎯 결 TOUR — Package Selector & Estimator
A2: ⬇️ 드롭다운으로 항목 선택 → 가격 자동계산 → 나만의 견적서 완성!
A4: 📋 PACKAGE INFO
A5: Package Name | E5: Golfers | F5: 4 | G5: persons
A6: Duration | B6: 5N7D | C6: → | D6: Nights (auto) | E6: =IF(B6="3N4D",3,IF(B6="4N5D",4,IF(B6="5N6D",5,IF(B6="6N7D",6,IF(B6="7N8D",7,IF(B6="10N11D",10,IF(B6="12N13D",12,3))))))) | F6: nights | G6: Days (auto) | H6: =E6+1
A9: ⛳ GOLF (1인 1라운드)
A10: # | B10: Item (Select ▼) | C10: Qty | D10: Cost/unit | E10: Sell/unit | F10: Margin/u | G10: Total Cost | H10: Total Sell | I10: Total Margin | J10: Notes
A11: 1 | D11: =IF(B11="","",VLOOKUP(B11,'Master Data'!$A$7:$C$14,2,FALSE)) | E11: =IF(B11="","",VLOOKUP(B11,'Master Data'!$A$7:$C$14,3,FALSE)) | F11: =IF(B11="","",E11-D11) | G11: =IF(B11="","",C11*D11) | H11: =IF(B11="","",C11*E11) | I11: =IF(B11="","",H11-G11)
A12: 2 | D12: =IF(B12="","",VLOOKUP(B12,'Master Data'!$A$7:$C$14,2,FALSE)) | E12: =IF(B12="","",VLOOKUP(B12,'Master Data'!$A$7:$C$14,3,FALSE)) | F12: =IF(B12="","",E12-D12) | G12: =IF(B12="","",C12*D12) | H12: =IF(B12="","",C12*E12) | I12: =IF(B12="","",H12-G12)
A13: 3 | D13: =IF(B13="","",VLOOKUP(B13,'Master Data'!$A$7:$C$14,2,FALSE)) | E13: =IF(B13="","",VLOOKUP(B13,'Master Data'!$A$7:$C$14,3,FALSE)) | F13: =IF(B13="","",E13-D13) | G13: =IF(B13="","",C13*D13) | H13: =IF(B13="","",C13*E13) | I13: =IF(B13="","",H13-G13)
A14: 4 | D14: =IF(B14="","",VLOOKUP(B14,'Master Data'!$A$7:$C$14,2,FALSE)) | E14: =IF(B14="","",VLOOKUP(B14,'Master Data'!$A$7:$C$14,3,FALSE)) | F14: =IF(B14="","",E14-D14) | G14: =IF(B14="","",C14*D14) | H14: =IF(B14="","",C14*E14) | I14: =IF(B14="","",H14-G14)
A15: 5 | D15: =IF(B15="","",VLOOKUP(B15,'Master Data'!$A$7:$C$14,2,FALSE)) | E15: =IF(B15="","",VLOOKUP(B15,'Master Data'!$A$7:$C$14,3,FALSE)) | F15: =IF(B15="","",E15-D15) | G15: =IF(B15="","",C15*D15) | H15: =IF(B15="","",C15*E15) | I15: =IF(B15="","",H15-G15)
A16: SUBTOTAL | G16: =SUM(G11:G15) | H16: =SUM(H11:H15) | I16: =SUM(I11:I15)
A18: 🏨 HOTEL (1인 1박)
A19: # | B19: Item (Select ▼) | C19: Qty | D19: Cost/unit | E19: Sell/unit | F19: Margin/u | G19: Total Cost | H19: Total Sell | I19: Total Margin | J19: Notes
A20: 1 | D20: =IF(B20="","",VLOOKUP(B20,'Master Data'!$A$18:$C$23,2,FALSE)) | E20: =IF(B20="","",VLOOKUP(B20,'Master Data'!$A$18:$C$23,3,FALSE)) | F20: =IF(B20="","",E20-D20) | G20: =IF(B20="","",C20*D20) | H20: =IF(B20="","",C20*E20) | I20: =IF(B20="","",H20-G20)
A21: 2 | D21: =IF(B21="","",VLOOKUP(B21,'Master Data'!$A$18:$C$23,2,FALSE)) | E21: =IF(B21="","",VLOOKUP(B21,'Master Data'!$A$18:$C$23,3,FALSE)) | F21: =IF(B21="","",E21-D21) | G21: =IF(B21="","",C21*D21) | H21: =IF(B21="","",C21*E21) | I21: =IF(B21="","",H21-G21)
A22: 3 | D22: =IF(B22="","",VLOOKUP(B22,'Master Data'!$A$18:$C$23,2,FALSE)) | E22: =IF(B22="","",VLOOKUP(B22,'Master Data'!$A$18:$C$23,3,FALSE)) | F22: =IF(B22="","",E22-D22) | G22: =IF(B22="","",C22*D22) | H22: =IF(B22="","",C22*E22) | I22: =IF(B22="","",H22-G22)
A23: SUBTOTAL | G23: =SUM(G20:G22) | H23: =SUM(H20:H22) | I23: =SUM(I20:I22)
A25: 🚐 TRANSPORT (1인 기준)
A26: # | B26: Item (Select ▼) | C26: Qty | D26: Cost/unit | E26: Sell/unit | F26: Margin/u | G26: Total Cost | H26: Total Sell | I26: Total Margin | J26: Notes
A27: 1 | D27: =IF(B27="","",VLOOKUP(B27,'Master Data'!$A$27:$C$33,2,FALSE)) | E27: =IF(B27="","",VLOOKUP(B27,'Master Data'!$A$27:$C$33,3,FALSE)) | F27: =IF(B27="","",E27-D27) | G27: =IF(B27="","",C27*D27) | H27: =IF(B27="","",C27*E27) | I27: =IF(B27="","",H27-G27)
A28: 2 | D28: =IF(B28="","",VLOOKUP(B28,'Master Data'!$A$27:$C$33,2,FALSE)) | E28: =IF(B28="","",VLOOKUP(B28,'Master Data'!$A$27:$C$33,3,FALSE)) | F28: =IF(B28="","",E28-D28) | G28: =IF(B28="","",C28*D28) | H28: =IF(B28="","",C28*E28) | I28: =IF(B28="","",H28-G28)
A29: 3 | D29: =IF(B29="","",VLOOKUP(B29,'Master Data'!$A$27:$C$33,2,FALSE)) | E29: =IF(B29="","",VLOOKUP(B29,'Master Data'!$A$27:$C$33,3,FALSE)) | F29: =IF(B29="","",E29-D29) | G29: =IF(B29="","",C29*D29) | H29: =IF(B29="","",C29*E29) | I29: =IF(B29="","",H29-G29)
A30: SUBTOTAL | G30: =SUM(G27:G29) | H30: =SUM(H27:H29) | I30: =SUM(I27:I29)
A32: 🍽️ MEALS (1인 1끼)
A33: # | B33: Item (Select ▼) | C33: Qty | D33: Cost/unit | E33: Sell/unit | F33: Margin/u | G33: Total Cost | H33: Total Sell | I33: Total Margin | J33: Notes
A34: 1 | D34: =IF(B34="","",VLOOKUP(B34,'Master Data'!$A$37:$C$45,2,FALSE)) | E34: =IF(B34="","",VLOOKUP(B34,'Master Data'!$A$37:$C$45,3,FALSE)) | F34: =IF(B34="","",E34-D34) | G34: =IF(B34="","",C34*D34) | H34: =IF(B34="","",C34*E34) | I34: =IF(B34="","",H34-G34)
A35: 2 | D35: =IF(B35="","",VLOOKUP(B35,'Master Data'!$A$37:$C$45,2,FALSE)) | E35: =IF(B35="","",VLOOKUP(B35,'Master Data'!$A$37:$C$45,3,FALSE)) | F35: =IF(B35="","",E35-D35) | G35: =IF(B35="","",C35*D35) | H35: =IF(B35="","",C35*E35) | I35: =IF(B35="","",H35-G35)
A36: 3 | D36: =IF(B36="","",VLOOKUP(B36,'Master Data'!$A$37:$C$45,2,FALSE)) | E36: =IF(B36="","",VLOOKUP(B36,'Master Data'!$A$37:$C$45,3,FALSE)) | F36: =IF(B36="","",E36-D36) | G36: =IF(B36="","",C36*D36) | H36: =IF(B36="","",C36*E36) | I36: =IF(B36="","",H36-G36)
A37: 4 | D37: =IF(B37="","",VLOOKUP(B37,'Master Data'!$A$37:$C$45,2,FALSE)) | E37: =IF(B37="","",VLOOKUP(B37,'Master Data'!$A$37:$C$45,3,FALSE)) | F37: =IF(B37="","",E37-D37) | G37: =IF(B37="","",C37*D37) | H37: =IF(B37="","",C37*E37) | I37: =IF(B37="","",H37-G37)
A38: 5 | D38: =IF(B38="","",VLOOKUP(B38,'Master Data'!$A$37:$C$45,2,FALSE)) | E38: =IF(B38="","",VLOOKUP(B38,'Master Data'!$A$37:$C$45,3,FALSE)) | F38: =IF(B38="","",E38-D38) | G38: =IF(B38="","",C38*D38) | H38: =IF(B38="","",C38*E38) | I38: =IF(B38="","",H38-G38)
A39: SUBTOTAL | G39: =SUM(G34:G38) | H39: =SUM(H34:H38) | I39: =SUM(I34:I38)
A41: 📦 OTHER (1인 1일)
A42: # | B42: Item (Select ▼) | C42: Qty | D42: Cost/unit | E42: Sell/unit | F42: Margin/u | G42: Total Cost | H42: Total Sell | I42: Total Margin | J42: Notes
A43: 1 | D43: =IF(B43="","",VLOOKUP(B43,'Master Data'!$A$49:$C$54,2,FALSE)) | E43: =IF(B43="","",VLOOKUP(B43,'Master Data'!$A$49:$C$54,3,FALSE)) | F43: =IF(B43="","",E43-D43) | G43: =IF(B43="","",C43*D43) | H43: =IF(B43="","",C43*E43) | I43: =IF(B43="","",H43-G43)
A44: 2 | D44: =IF(B44="","",VLOOKUP(B44,'Master Data'!$A$49:$C$54,2,FALSE)) | E44: =IF(B44="","",VLOOKUP(B44,'Master Data'!$A$49:$C$54,3,FALSE)) | F44: =IF(B44="","",E44-D44) | G44: =IF(B44="","",C44*D44) | H44: =IF(B44="","",C44*E44) | I44: =IF(B44="","",H44-G44)
A45: 3 | D45: =IF(B45="","",VLOOKUP(B45,'Master Data'!$A$49:$C$54,2,FALSE)) | E45: =IF(B45="","",VLOOKUP(B45,'Master Data'!$A$49:$C$54,3,FALSE)) | F45: =IF(B45="","",E45-D45) | G45: =IF(B45="","",C45*D45) | H45: =IF(B45="","",C45*E45) | I45: =IF(B45="","",H45-G45)
A46: SUBTOTAL | G46: =SUM(G43:G45) | H46: =SUM(H43:H45) | I46: =SUM(I43:I45)
A48: 🏆 GRAND TOTAL
...

Sheet Profit Summary
A1: 📊 PROFIT SUMMARY — Package Selector 결과 자동 반영
A2: ⬇️ 'Package Selector' 시트에서 선택한 항목에 따라 자동 업데이트
A4: 💰 PACKAGE PROFIT OVERVIEW
A5: Category | B5: Total Cost | C5: Total Sell | D5: Total Margin | E5: Margin% | F5: Per Person Cost | G5: Per Person Sell | H5: Per Person Margin
A6: GOLF | B6: ='Package Selector'!G16 | C6: ='Package Selector'!H16 | D6: ='Package Selector'!I16 | E6: =IF(C6>0,D6/C6,0) | F6: =IF('Package Selector'!F5>0,B6/'Package Selector'!F5,0) | G6: =IF('Package Selector'!F5>0,C6/'Package Selector'!F5,0) | H6: =IF('Package Selector'!F5>0,D6/'Package Selector'!F5,0)
A7: HOTEL | B7: ='Package Selector'!G23 | C7: ='Package Selector'!H23 | D7: ='Package Selector'!I23 | E7: =IF(C7>0,D7/C7,0) | F7: =IF('Package Selector'!F5>0,B7/'Package Selector'!F5,0) | G7: =IF('Package Selector'!F5>0,C7/'Package Selector'!F5,0) | H7: =IF('Package Selector'!F5>0,D7/'Package Selector'!F5,0)
A8: TRANSPORT | B8: ='Package Selector'!G30 | C8: ='Package Selector'!H30 | D8: ='Package Selector'!I30 | E8: =IF(C8>0,D8/C8,0) | F8: =IF('Package Selector'!F5>0,B8/'Package Selector'!F5,0) | G8: =IF('Package Selector'!F5>0,C8/'Package Selector'!F5,0) | H8: =IF('Package Selector'!F5>0,D8/'Package Selector'!F5,0)
A9: MEALS | B9: ='Package Selector'!G39 | C9: ='Package Selector'!H39 | D9: ='Package Selector'!I39 | E9: =IF(C9>0,D9/C9,0) | F9: =IF('Package Selector'!F5>0,B9/'Package Selector'!F5,0) | G9: =IF('Package Selector'!F5>0,C9/'Package Selector'!F5,0) | H9: =IF('Package Selector'!F5>0,D9/'Package Selector'!F5,0)
A10: OTHER | B10: ='Package Selector'!G46 | C10: ='Package Selector'!H46 | D10: ='Package Selector'!I46 | E10: =IF(C10>0,D10/C10,0) | F10: =IF('Package Selector'!F5>0,B10/'Package Selector'!F5,0) | G10: =IF('Package Selector'!F5>0,C10/'Package Selector'!F5,0) | H10: =IF('Package Selector'!F5>0,D10/'Package Selector'!F5,0)
A11: 📌 TOTAL | B11: =SUM(B6:B10) | C11: =SUM(C6:C10) | D11: =SUM(D6:D10) | E11: =SUM(E6:E10) | F11: =SUM(F6:F10) | G11: =SUM(G6:G10) | H11: =SUM(H6:H10)
A13: 💡 'Package Selector' 시트에서 드롭다운으로 항목을 선택/변경하면 이 요약표가 자동으로 업데이트됩니다.
A14: 💡 마스터데이터 시트에서 가격을 수정하면 모든 시트에 즉시 반영됩니다.
