Workbook

Sheet Master Data
A1: 📊 MASTER DATA — 비용 파라미터 (수정 시 전 시트 자동 반영)
A2: ⚠️ 🟡노란색=직접입력 | 🔵파란색=자동계산 | ⬜빈칸=신규항목 추가용
A3: 새 코스·호텔·편명 추가는 빈칸에 직접 입력 → 자동으로 드롭다운에 반영
A5: ⛳ GOLF COURSES (1인 1라운드, USD)
A6: Course | B6: Cost ($) | C6: Sell ($) | D6: Margin $ | E6: Margin % | F6: Margin % | H6: Charge
A7: Hidden Valley GC | B7: 109 | C7: 109 | D7: =IF(A7="","",C7-B7) | E7: =IF(A7="","",IF(C7>0,(C7-B7)/C7,0)) | F7: 45 | G7: teeitup.com | 9Stamps=1free | Replay twilight | H7: Per Person
A8: Sandpiper GC | B8: 130 | C8: 130 | D8: =IF(A8="","",C8-B8) | E8: =IF(A8="","",IF(C8>0,(C8-B8)/C8,0)) | F8: 120 | G8: UnderPar deal | Replay FREE | Non-Resident | H8: Per Person
A9: Trump National LA | B9: 210 | C9: 210 | D9: =IF(A9="","",C9-B9) | E9: =IF(A9="","",IF(C9>0,(C9-B9)/C9,0)) | F9: 111 | G9: Member guest | Cart incl. | Replay ~50% | H9: Per Person
D10: =IF(A10="","",C10-B10) | E10: =IF(A10="","",IF(C10>0,(C10-B10)/C10,0))
D11: =IF(A11="","",C11-B11) | E11: =IF(A11="","",IF(C11>0,(C11-B11)/C11,0))
D12: =IF(A12="","",C12-B12) | E12: =IF(A12="","",IF(C12>0,(C12-B12)/C12,0))
D13: =IF(A13="","",C13-B13) | E13: =IF(A13="","",IF(C13>0,(C13-B13)/C13,0))
D14: =IF(A14="","",C14-B14) | E14: =IF(A14="","",IF(C14>0,(C14-B14)/C14,0))
A17: 🏨 HOTEL (1인 1박, Double Occupancy, USD)
A18: Hotel | B18: Cost/night | C18: Sell/night | D18: Margin $ | E18: Margin % | F18: Margin %
A19: Beverly Wilshire (5★) / Same Tier | B19: 275 | C19: 375 | D19: =IF(A19="","",C19-B19) | E19: =IF(A19="","",IF(C19>0,(C19-B19)/C19,0)) | G19: $550/room ÷ 2 persons
D20: =IF(A20="","",C20-B20) | E20: =IF(A20="","",IF(C20>0,(C20-B20)/C20,0))
D21: =IF(A21="","",C21-B21) | E21: =IF(A21="","",IF(C21>0,(C21-B21)/C21,0))
D22: =IF(A22="","",C22-B22) | E22: =IF(A22="","",IF(C22>0,(C22-B22)/C22,0))
D23: =IF(A23="","",C23-B23) | E23: =IF(A23="","",IF(C23>0,(C23-B23)/C23,0))
D24: =IF(A24="","",C24-B24) | E24: =IF(A24="","",IF(C24>0,(C24-B24)/C24,0))
E25: =IF(A25="","",IF(C25>0,(C25-B25)/C25,0))
A26: 🚐 TRANSPORT (1인 기준, 4인 1조, USD)
A27: Item | B27: Cost/p | C27: Sell/p | D27: Margin $ | E27: Margin % | F27: Margin % | H27: Charge
A28: Airport Roundtrip Pickup | B28: 75 | C28: 120 | D28: =IF(A28="","",C28-B28) | E28: =IF(A28="","",IF(C28>0,(C28-B28)/C28,0)) | G28: $500/day ÷ 4p | Driver=Guide | H28: Per Group
A29: Driver/Guide + Van (일당) | B29: 125 | C29: 175 | D29: =IF(A29="","",C29-B29) | E29: =IF(A29="","",IF(C29>0,(C29-B29)/C29,0)) | G29: LAX ↔ Hotel, per person | H29: Per Person
D30: =IF(A30="","",C30-B30) | E30: =IF(A30="","",IF(C30>0,(C30-B30)/C30,0))
D31: =IF(A31="","",C31-B31) | E31: =IF(A31="","",IF(C31>0,(C31-B31)/C31,0))
D32: =IF(A32="","",C32-B32) | E32: =IF(A32="","",IF(C32>0,(C32-B32)/C32,0))
D33: =IF(A33="","",C33-B33) | E33: =IF(A33="","",IF(C33>0,(C33-B33)/C33,0))
D34: =IF(A34="","",C34-B34) | E34: =IF(A34="","",IF(C34>0,(C34-B34)/C34,0))
E35: =IF(A35="","",IF(C35>0,(C35-B35)/C35,0))
A36: 🍽️ MEALS (1인 1끼, USD)
A37: Meal | B37: Cost | C37: Sell | D37: Margin $ | E37: Margin % | F37: Margin %
A38: Breakfast (Hotel) | B38: 30 | C38: 45 | D38: =IF(A38="","",C38-B38) | E38: =IF(A38="","",IF(C38>0,(C38-B38)/C38,0)) | G38: Daily included
A39: Dinner (Regular) | B39: 80 | C39: 120 | D39: =IF(A39="","",C39-B39) | E39: =IF(A39="","",IF(C39>0,(C39-B39)/C39,0)) | G39: Daily included
A40: Exclusive Dinner (Michelin/Fine) | B40: 120 | C40: 180 | D40: =IF(A40="","",C40-B40) | E40: =IF(A40="","",IF(C40>0,(C40-B40)/C40,0)) | G40: Regular dinner
A41: Lunch | B41: 40 | C41: 60 | D41: =IF(A41="","",C41-B41) | E41: =IF(A41="","",IF(C41>0,(C41-B41)/C41,0)) | G41: 2x per trip
D42: =IF(A42="","",C42-B42) | E42: =IF(A42="","",IF(C42>0,(C42-B42)/C42,0))
D43: =IF(A43="","",C43-B43) | E43: =IF(A43="","",IF(C43>0,(C43-B43)/C43,0))
...

Sheet Package Types
A1: 🎯 결 TOUR — 대표 패키지 (1인 기준, USD | 중복코스 없음)
A2: ⚠️ 참고용 대표패키지 → 'Package Selector' 시트에서 자유롭게 커스터마이징
A4: No | B4: 일정 | C4: 패키지명 | D4: 박 | E4: 일 | F4: Rds | G4: 패키지 구성 | H4: ⛳ 골프 | P4: 🍽️ 식사 | R4: 📦 기타 | T4: 마진 | U4: 마진율
H5: Cost | I5: Sell | J5: Cost | K5: Sell | L5: Cost | M5: Sell | N5: Cost | O5: Sell | P5: Cost | Q5: Sell | R5: Cost | S5: Sell
A6: 1 | B6: 3N4D | C6: 트럼프 + 샌드파이퍼 오션뷰 | D6: 3 | E6: 4 | F6: 2 | G6: Trump×1 + Sand×1 | H6: G2·H3·T3·M3B3L3D2Ex·I4 | I6: 745 | J6: 0 | K6: 120 | L6: 825 | M6: 1125 | N6: 375 | O6: 525 | P6: 810 | Q6: 1215 | R6: 200 | S6: 300 | T6: =(J6+L6+N6+P6+R6+T6)-(I6+K6+M6+O6+Q6+S6) | U6: =IF(J6+L6+N6+P6+R6+T6>0,((J6+L6+N6+P6+R6+T6)-(I6+K6+M6+O6+Q6+S6))/(J6+L6+N6+P6+R6+T6),0)
A7: 2 | B7: 3N4D | C7: 트럼프 + 히든밸리 밸리뷰 | D7: 3 | E7: 4 | F7: 2 | G7: Trump×1 + HV×1 | H7: G2·H3·T3·M3B3L3D2Ex·I4 | I7: 609 | J7: 45 | K7: 45 | L7: 825 | M7: 1125 | N7: 375 | O7: 525 | P7: 810 | Q7: 1215 | R7: 200 | S7: 300 | T7: =(J7+L7+N7+P7+R7+T7)-(I7+K7+M7+O7+Q7+S7) | U7: =IF(J7+L7+N7+P7+R7+T7>0,((J7+L7+N7+P7+R7+T7)-(I7+K7+M7+O7+Q7+S7))/(J7+L7+N7+P7+R7+T7),0)
A8: 3 | B8: 3N4D | C8: 샌드파이퍼 + 히든밸리 | D8: 3 | E8: 4 | F8: 2 | G8: Sand×1 + HV×1 | H8: G2·H3·T3·M3B3L3D2Ex·I4 | I8: 354 | J8: 45 | K8: 45 | L8: 825 | M8: 1125 | N8: 375 | O8: 525 | P8: 810 | Q8: 1215 | R8: 200 | S8: 300 | T8: =(J8+L8+N8+P8+R8+T8)-(I8+K8+M8+O8+Q8+S8) | U8: =IF(J8+L8+N8+P8+R8+T8>0,((J8+L8+N8+P8+R8+T8)-(I8+K8+M8+O8+Q8+S8))/(J8+L8+N8+P8+R8+T8),0)
A10: 4 | B10: 5N7D | C10: 트럼프+샌드+히든 3色 시그니처 | D10: 5 | E10: 7 | F10: 3 | G10: Trump×1+Sand×1+HV×1 | H10: G3·H5·T5·M5B5L5D2Ex·I5 | I10: 854 | J10: 45 | K10: 165 | L10: 1375 | M10: 1875 | N10: 625 | O10: 875 | P10: 1350 | Q10: 2025 | R10: 250 | S10: 375 | T10: =(J10+L10+N10+P10+R10+T10)-(I10+K10+M10+O10+Q10+S10) | U10: =IF(J10+L10+N10+P10+R10+T10>0,((J10+L10+N10+P10+R10+T10)-(I10+K10+M10+O10+Q10+S10))/(J10+L10+N10+P10+R10+T10),0)

Sheet Package Selector
A1: 🎯 PACKAGE SELECTOR
A2: Package: | D2: Golfers: | E2: 4 | F2: Guest1 | G2: Guest2 | H2: Guest3 | I2: Guest4
A3: ✈️ OUTBOUND
A4: Date: | B4: 2026-05-25 | C4: Flight: | D4: KE011 | E4: =IF(D4="","",VLOOKUP(D4,'Master Data'!$A$60:$D$63,3,FALSE))&" → "&IF(D4="","",VLOOKUP(D4,'Master Data'!$A$60:$D$63,4,FALSE)) | I4: Seat: | J4: Economy
A5: ✈️ RETURN
A6: Date: | B6: 2026-05-30 | C6: Flight: | D6: KE018 | E6: =IF(D6="","",VLOOKUP(D6,'Master Data'!$A$74:$D$77,3,FALSE))&" → "&IF(D6="","",VLOOKUP(D6,'Master Data'!$A$74:$D$77,4,FALSE)) | I6: Duration: | J6: =IF(AND(B4<>"",B6<>""),B6-B4,"")&"N "&IF(AND(B4<>"",B6<>""),B6-B4+1,"")&"D"
A7: Status: | B7: =IF(SUM(Q:Q)>0,"❌"&SUM(Q:Q)&"dup","✅") | D7: X-Check: | E7: =J72 | F7: vs | G7: =B89 | H7: = | I7: =IF(E7-G7=0,"✅MATCH","❌")
A8: Item ▼ | B8: Qty | C8: Cost/P | D8: Sell/P | E8: M% | F8: =F2 | G8: =G2 | H8: =H2 | I8: =I2 | J8: Cost | K8: Sell | L8: P5 | M8: P6 | N8: P7 | O8: P8 | Q8: Type
A9: ⛳ GOLF
A10: Hidden Valley GC | B10: 1 | C10: =IF(A10="","",VLOOKUP(A10,'Master Data'!$A$7:$C$14,2,FALSE)) | D10: =IF(A10="","",VLOOKUP(A10,'Master Data'!$A$7:$C$14,3,FALSE)) | E10: =IF(D10>0,(D10-C10)/D10,0) | J10: =IF(A10="","",(COUNTIF(F10,"●")+COUNTIF(G10,"●")+COUNTIF(H10,"●")+COUNTIF(I10,"●")+COUNTIF(L10,"●")+COUNTIF(M10,"●")+COUNTIF(N10,"●")+COUNTIF(O10,"●"))*B10*C10) | K10: =IF(A10="","",(COUNTIF(F10,"●")+COUNTIF(G10,"●")+COUNTIF(H10,"●")+COUNTIF(I10,"●")+COUNTIF(L10,"●")+COUNTIF(M10,"●")+COUNTIF(N10,"●")+COUNTIF(O10,"●"))*B10*D10) | Q10: =0 | R10: pp
A11: Sandpiper GC | B11: 2 | C11: =IF(A11="","",VLOOKUP(A11,'Master Data'!$A$7:$C$14,2,FALSE)) | D11: =IF(A11="","",VLOOKUP(A11,'Master Data'!$A$7:$C$14,3,FALSE)) | E11: =IF(D11>0,(D11-C11)/D11,0) | J11: =IF(A11="","",(COUNTIF(F11,"●")+COUNTIF(G11,"●")+COUNTIF(H11,"●")+COUNTIF(I11,"●")+COUNTIF(L11,"●")+COUNTIF(M11,"●")+COUNTIF(N11,"●")+COUNTIF(O11,"●"))*B11*C11) | K11: =IF(A11="","",(COUNTIF(F11,"●")+COUNTIF(G11,"●")+COUNTIF(H11,"●")+COUNTIF(I11,"●")+COUNTIF(L11,"●")+COUNTIF(M11,"●")+COUNTIF(N11,"●")+COUNTIF(O11,"●"))*B11*D11) | Q11: =IF(A11="",0,COUNTIF(A$10:A10,A11)) | R11: pp
A12: Trump National LA | B12: 2 | C12: =IF(A12="","",VLOOKUP(A12,'Master Data'!$A$7:$C$14,2,FALSE)) | D12: =IF(A12="","",VLOOKUP(A12,'Master Data'!$A$7:$C$14,3,FALSE)) | E12: =IF(D12>0,(D12-C12)/D12,0) | J12: =IF(A12="","",(COUNTIF(F12,"●")+COUNTIF(G12,"●")+COUNTIF(H12,"●")+COUNTIF(I12,"●")+COUNTIF(L12,"●")+COUNTIF(M12,"●")+COUNTIF(N12,"●")+COUNTIF(O12,"●"))*B12*C12) | K12: =IF(A12="","",(COUNTIF(F12,"●")+COUNTIF(G12,"●")+COUNTIF(H12,"●")+COUNTIF(I12,"●")+COUNTIF(L12,"●")+COUNTIF(M12,"●")+COUNTIF(N12,"●")+COUNTIF(O12,"●"))*B12*D12) | Q12: =IF(A12="",0,COUNTIF(A$10:A11,A12)) | R12: pp
C13: =IF(A13="","",VLOOKUP(A13,'Master Data'!$A$7:$C$14,2,FALSE)) | D13: =IF(A13="","",VLOOKUP(A13,'Master Data'!$A$7:$C$14,3,FALSE)) | E13: =IF(D13>0,(D13-C13)/D13,0) | J13: =IF(A13="","",(COUNTIF(F13,"●")+COUNTIF(G13,"●")+COUNTIF(H13,"●")+COUNTIF(I13,"●")+COUNTIF(L13,"●")+COUNTIF(M13,"●")+COUNTIF(N13,"●")+COUNTIF(O13,"●"))*B13*C13) | K13: =IF(A13="","",(COUNTIF(F13,"●")+COUNTIF(G13,"●")+COUNTIF(H13,"●")+COUNTIF(I13,"●")+COUNTIF(L13,"●")+COUNTIF(M13,"●")+COUNTIF(N13,"●")+COUNTIF(O13,"●"))*B13*D13) | Q13: =IF(A13="",0,COUNTIF(A$10:A12,A13))
C14: =IF(A14="","",VLOOKUP(A14,'Master Data'!$A$7:$C$14,2,FALSE)) | D14: =IF(A14="","",VLOOKUP(A14,'Master Data'!$A$7:$C$14,3,FALSE)) | E14: =IF(D14>0,(D14-C14)/D14,0) | J14: =IF(A14="","",(COUNTIF(F14,"●")+COUNTIF(G14,"●")+COUNTIF(H14,"●")+COUNTIF(I14,"●")+COUNTIF(L14,"●")+COUNTIF(M14,"●")+COUNTIF(N14,"●")+COUNTIF(O14,"●"))*B14*C14) | K14: =IF(A14="","",(COUNTIF(F14,"●")+COUNTIF(G14,"●")+COUNTIF(H14,"●")+COUNTIF(I14,"●")+COUNTIF(L14,"●")+COUNTIF(M14,"●")+COUNTIF(N14,"●")+COUNTIF(O14,"●"))*B14*D14) | Q14: =IF(A14="",0,COUNTIF(A$10:A13,A14))
A15: SUBTOTAL | F15: =IF(F10="●",B10*C10,0)+IF(F11="●",B11*C11,0)+IF(F12="●",B12*C12,0)+IF(F13="●",B13*C13,0)+IF(F14="●",B14*C14,0) | G15: =IF(G10="●",B10*C10,0)+IF(G11="●",B11*C11,0)+IF(G12="●",B12*C12,0)+IF(G13="●",B13*C13,0)+IF(G14="●",B14*C14,0) | H15: =IF(H10="●",B10*C10,0)+IF(H11="●",B11*C11,0)+IF(H12="●",B12*C12,0)+IF(H13="●",B13*C13,0)+IF(H14="●",B14*C14,0) | I15: =IF(I10="●",B10*C10,0)+IF(I11="●",B11*C11,0)+IF(I12="●",B12*C12,0)+IF(I13="●",B13*C13,0)+IF(I14="●",B14*C14,0) | J15: =SUM(J10:J14) | K15: =SUM(K10:K14) | L15: =IF(L10="●",B10*C10,0)+IF(L11="●",B11*C11,0)+IF(L12="●",B12*C12,0)+IF(L13="●",B13*C13,0)+IF(L14="●",B14*C14,0) | M15: =IF(M10="●",B10*C10,0)+IF(M11="●",B11*C11,0)+IF(M12="●",B12*C12,0)+IF(M13="●",B13*C13,0)+IF(M14="●",B14*C14,0) | N15: =IF(N10="●",B10*C10,0)+IF(N11="●",B11*C11,0)+IF(N12="●",B12*C12,0)+IF(N13="●",B13*C13,0)+IF(N14="●",B14*C14,0) | O15: =IF(O10="●",B10*C10,0)+IF(O11="●",B11*C11,0)+IF(O12="●",B12*C12,0)+IF(O13="●",B13*C13,0)+IF(O14="●",B14*C14,0)
A17: 🏨 HOTEL
A18: Beverly Wilshire (5★) / Same Tier | B18: 3 | C18: =IF(A18="","",VLOOKUP(A18,'Master Data'!$A$19:$C$24,2,FALSE)) | D18: =IF(A18="","",VLOOKUP(A18,'Master Data'!$A$19:$C$24,3,FALSE)) | E18: =IF(D18>0,(D18-C18)/D18,0) | J18: =IF(A18="","",(COUNTIF(F18,"●")+COUNTIF(G18,"●")+COUNTIF(H18,"●")+COUNTIF(I18,"●")+COUNTIF(L18,"●")+COUNTIF(M18,"●")+COUNTIF(N18,"●")+COUNTIF(O18,"●"))*B18*C18) | K18: =IF(A18="","",(COUNTIF(F18,"●")+COUNTIF(G18,"●")+COUNTIF(H18,"●")+COUNTIF(I18,"●")+COUNTIF(L18,"●")+COUNTIF(M18,"●")+COUNTIF(N18,"●")+COUNTIF(O18,"●"))*B18*D18) | Q18: =0 | R18: pp
C19: =IF(A19="","",VLOOKUP(A19,'Master Data'!$A$19:$C$24,2,FALSE)) | D19: =IF(A19="","",VLOOKUP(A19,'Master Data'!$A$19:$C$24,3,FALSE)) | E19: =IF(D19>0,(D19-C19)/D19,0) | J19: =IF(A19="","",(COUNTIF(F19,"●")+COUNTIF(G19,"●")+COUNTIF(H19,"●")+COUNTIF(I19,"●")+COUNTIF(L19,"●")+COUNTIF(M19,"●")+COUNTIF(N19,"●")+COUNTIF(O19,"●"))*B19*C19) | K19: =IF(A19="","",(COUNTIF(F19,"●")+COUNTIF(G19,"●")+COUNTIF(H19,"●")+COUNTIF(I19,"●")+COUNTIF(L19,"●")+COUNTIF(M19,"●")+COUNTIF(N19,"●")+COUNTIF(O19,"●"))*B19*D19) | Q19: =IF(A19="",0,COUNTIF(A$18:A18,A19))
C20: =IF(A20="","",VLOOKUP(A20,'Master Data'!$A$19:$C$24,2,FALSE)) | D20: =IF(A20="","",VLOOKUP(A20,'Master Data'!$A$19:$C$24,3,FALSE)) | E20: =IF(D20>0,(D20-C20)/D20,0) | J20: =IF(A20="","",(COUNTIF(F20,"●")+COUNTIF(G20,"●")+COUNTIF(H20,"●")+COUNTIF(I20,"●")+COUNTIF(L20,"●")+COUNTIF(M20,"●")+COUNTIF(N20,"●")+COUNTIF(O20,"●"))*B20*C20) | K20: =IF(A20="","",(COUNTIF(F20,"●")+COUNTIF(G20,"●")+COUNTIF(H20,"●")+COUNTIF(I20,"●")+COUNTIF(L20,"●")+COUNTIF(M20,"●")+COUNTIF(N20,"●")+COUNTIF(O20,"●"))*B20*D20) | Q20: =IF(A20="",0,COUNTIF(A$18:A19,A20))
A21: SUBTOTAL | F21: =IF(F18="●",B18*C18,0)+IF(F19="●",B19*C19,0)+IF(F20="●",B20*C20,0) | G21: =IF(G18="●",B18*C18,0)+IF(G19="●",B19*C19,0)+IF(G20="●",B20*C20,0) | H21: =IF(H18="●",B18*C18,0)+IF(H19="●",B19*C19,0)+IF(H20="●",B20*C20,0) | I21: =IF(I18="●",B18*C18,0)+IF(I19="●",B19*C19,0)+IF(I20="●",B20*C20,0) | J21: =SUM(J18:J20) | K21: =SUM(K18:K20) | L21: =IF(L18="●",B18*C18,0)+IF(L19="●",B19*C19,0)+IF(L20="●",B20*C20,0) | M21: =IF(M18="●",B18*C18,0)+IF(M19="●",B19*C19,0)+IF(M20="●",B20*C20,0) | N21: =IF(N18="●",B18*C18,0)+IF(N19="●",B19*C19,0)+IF(N20="●",B20*C20,0) | O21: =IF(O18="●",B18*C18,0)+IF(O19="●",B19*C19,0)+IF(O20="●",B20*C20,0)
A23: 🚐 TRANSPORT
A24: Driver/Guide + Van (일당) | B24: 3 | C24: =IF(A24="","",VLOOKUP(A24,'Master Data'!$A$28:$C$34,2,FALSE)) | D24: =IF(A24="","",VLOOKUP(A24,'Master Data'!$A$28:$C$34,3,FALSE)) | E24: =IF(D24>0,(D24-C24)/D24,0) | J24: =IF(A24="","",IF(OR((F24="●")+(G24="●")+(H24="●")+(I24="●")+(L24="●")+(M24="●")+(N24="●")+(O24="●")),B24*C24,0)) | K24: =IF(A24="","",IF(OR((F24="●")+(G24="●")+(H24="●")+(I24="●")+(L24="●")+(M24="●")+(N24="●")+(O24="●")),B24*D24,0)) | Q24: =0 | R24: pg
C25: =IF(A25="","",VLOOKUP(A25,'Master Data'!$A$28:$C$34,2,FALSE)) | D25: =IF(A25="","",VLOOKUP(A25,'Master Data'!$A$28:$C$34,3,FALSE)) | E25: =IF(D25>0,(D25-C25)/D25,0) | J25: =IF(A25="","",(COUNTIF(F25,"●")+COUNTIF(G25,"●")+COUNTIF(H25,"●")+COUNTIF(I25,"●")+COUNTIF(L25,"●")+COUNTIF(M25,"●")+COUNTIF(N25,"●")+COUNTIF(O25,"●"))*B25*C25) | K25: =IF(A25="","",(COUNTIF(F25,"●")+COUNTIF(G25,"●")+COUNTIF(H25,"●")+COUNTIF(I25,"●")+COUNTIF(L25,"●")+COUNTIF(M25,"●")+COUNTIF(N25,"●")+COUNTIF(O25,"●"))*B25*D25) | Q25: =IF(A25="",0,COUNTIF(A$24:A24,A25))
C26: =IF(A26="","",VLOOKUP(A26,'Master Data'!$A$28:$C$34,2,FALSE)) | D26: =IF(A26="","",VLOOKUP(A26,'Master Data'!$A$28:$C$34,3,FALSE)) | E26: =IF(D26>0,(D26-C26)/D26,0) | J26: =IF(A26="","",(COUNTIF(F26,"●")+COUNTIF(G26,"●")+COUNTIF(H26,"●")+COUNTIF(I26,"●")+COUNTIF(L26,"●")+COUNTIF(M26,"●")+COUNTIF(N26,"●")+COUNTIF(O26,"●"))*B26*C26) | K26: =IF(A26="","",(COUNTIF(F26,"●")+COUNTIF(G26,"●")+COUNTIF(H26,"●")+COUNTIF(I26,"●")+COUNTIF(L26,"●")+COUNTIF(M26,"●")+COUNTIF(N26,"●")+COUNTIF(O26,"●"))*B26*D26) | Q26: =IF(A26="",0,COUNTIF(A$24:A25,A26))
A27: SUBTOTAL | F27: =IF(OR(F24="●"),B24*C24,0)+IF(F25="●",B25*C25,0)+IF(F26="●",B26*C26,0) | G27: =IF(OR(G24="●"),B24*C24,0)+IF(G25="●",B25*C25,0)+IF(G26="●",B26*C26,0) | H27: =IF(OR(H24="●"),B24*C24,0)+IF(H25="●",B25*C25,0)+IF(H26="●",B26*C26,0) | I27: =IF(OR(I24="●"),B24*C24,0)+IF(I25="●",B25*C25,0)+IF(I26="●",B26*C26,0) | J27: =SUM(J24:J26) | K27: =SUM(K24:K26) | L27: =IF(OR(L24="●"),B24*C24,0)+IF(L25="●",B25*C25,0)+IF(L26="●",B26*C26,0) | M27: =IF(OR(M24="●"),B24*C24,0)+IF(M25="●",B25*C25,0)+IF(M26="●",B26*C26,0) | N27: =IF(OR(N24="●"),B24*C24,0)+IF(N25="●",B25*C25,0)+IF(N26="●",B26*C26,0) | O27: =IF(OR(O24="●"),B24*C24,0)+IF(O25="●",B25*C25,0)+IF(O26="●",B26*C26,0)
A29: 🍽️ MEALS
A30: Breakfast (Hotel) | B30: 3 | C30: =IF(A30="","",VLOOKUP(A30,'Master Data'!$A$38:$C$46,2,FALSE)) | D30: =IF(A30="","",VLOOKUP(A30,'Master Data'!$A$38:$C$46,3,FALSE)) | E30: =IF(D30>0,(D30-C30)/D30,0) | J30: =IF(A30="","",(COUNTIF(F30,"●")+COUNTIF(G30,"●")+COUNTIF(H30,"●")+COUNTIF(I30,"●")+COUNTIF(L30,"●")+COUNTIF(M30,"●")+COUNTIF(N30,"●")+COUNTIF(O30,"●"))*B30*C30) | K30: =IF(A30="","",(COUNTIF(F30,"●")+COUNTIF(G30,"●")+COUNTIF(H30,"●")+COUNTIF(I30,"●")+COUNTIF(L30,"●")+COUNTIF(M30,"●")+COUNTIF(N30,"●")+COUNTIF(O30,"●"))*B30*D30) | Q30: =0 | R30: pp
A31: Dinner (Regular) | B31: 3 | C31: =IF(A31="","",VLOOKUP(A31,'Master Data'!$A$38:$C$46,2,FALSE)) | D31: =IF(A31="","",VLOOKUP(A31,'Master Data'!$A$38:$C$46,3,FALSE)) | E31: =IF(D31>0,(D31-C31)/D31,0) | J31: =IF(A31="","",(COUNTIF(F31,"●")+COUNTIF(G31,"●")+COUNTIF(H31,"●")+COUNTIF(I31,"●")+COUNTIF(L31,"●")+COUNTIF(M31,"●")+COUNTIF(N31,"●")+COUNTIF(O31,"●"))*B31*C31) | K31: =IF(A31="","",(COUNTIF(F31,"●")+COUNTIF(G31,"●")+COUNTIF(H31,"●")+COUNTIF(I31,"●")+COUNTIF(L31,"●")+COUNTIF(M31,"●")+COUNTIF(N31,"●")+COUNTIF(O31,"●"))*B31*D31) | Q31: =IF(A31="",0,COUNTIF(A$30:A30,A31)) | R31: pp
A32: Exclusive Dinner (Michelin/Fine) | B32: 2 | C32: =IF(A32="","",VLOOKUP(A32,'Master Data'!$A$38:$C$46,2,FALSE)) | D32: =IF(A32="","",VLOOKUP(A32,'Master Data'!$A$38:$C$46,3,FALSE)) | E32: =IF(D32>0,(D32-C32)/D32,0) | J32: =IF(A32="","",(COUNTIF(F32,"●")+COUNTIF(G32,"●")+COUNTIF(H32,"●")+COUNTIF(I32,"●")+COUNTIF(L32,"●")+COUNTIF(M32,"●")+COUNTIF(N32,"●")+COUNTIF(O32,"●"))*B32*C32) | K32: =IF(A32="","",(COUNTIF(F32,"●")+COUNTIF(G32,"●")+COUNTIF(H32,"●")+COUNTIF(I32,"●")+COUNTIF(L32,"●")+COUNTIF(M32,"●")+COUNTIF(N32,"●")+COUNTIF(O32,"●"))*B32*D32) | Q32: =IF(A32="",0,COUNTIF(A$30:A31,A32)) | R32: pp
A33: Lunch | B33: 3 | C33: =IF(A33="","",VLOOKUP(A33,'Master Data'!$A$38:$C$46,2,FALSE)) | D33: =IF(A33="","",VLOOKUP(A33,'Master Data'!$A$38:$C$46,3,FALSE)) | E33: =IF(D33>0,(D33-C33)/D33,0) | J33: =IF(A33="","",(COUNTIF(F33,"●")+COUNTIF(G33,"●")+COUNTIF(H33,"●")+COUNTIF(I33,"●")+COUNTIF(L33,"●")+COUNTIF(M33,"●")+COUNTIF(N33,"●")+COUNTIF(O33,"●"))*B33*C33) | K33: =IF(A33="","",(COUNTIF(F33,"●")+COUNTIF(G33,"●")+COUNTIF(H33,"●")+COUNTIF(I33,"●")+COUNTIF(L33,"●")+COUNTIF(M33,"●")+COUNTIF(N33,"●")+COUNTIF(O33,"●"))*B33*D33) | Q33: =IF(A33="",0,COUNTIF(A$30:A32,A33)) | R33: pp
C34: =IF(A34="","",VLOOKUP(A34,'Master Data'!$A$38:$C$46,2,FALSE)) | D34: =IF(A34="","",VLOOKUP(A34,'Master Data'!$A$38:$C$46,3,FALSE)) | E34: =IF(D34>0,(D34-C34)/D34,0) | J34: =IF(A34="","",(COUNTIF(F34,"●")+COUNTIF(G34,"●")+COUNTIF(H34,"●")+COUNTIF(I34,"●")+COUNTIF(L34,"●")+COUNTIF(M34,"●")+COUNTIF(N34,"●")+COUNTIF(O34,"●"))*B34*C34) | K34: =IF(A34="","",(COUNTIF(F34,"●")+COUNTIF(G34,"●")+COUNTIF(H34,"●")+COUNTIF(I34,"●")+COUNTIF(L34,"●")+COUNTIF(M34,"●")+COUNTIF(N34,"●")+COUNTIF(O34,"●"))*B34*D34) | Q34: =IF(A34="",0,COUNTIF(A$30:A33,A34))
A35: SUBTOTAL | F35: =IF(F30="●",B30*C30,0)+IF(F31="●",B31*C31,0)+IF(F32="●",B32*C32,0)+IF(F33="●",B33*C33,0)+IF(F34="●",B34*C34,0) | G35: =IF(G30="●",B30*C30,0)+IF(G31="●",B31*C31,0)+IF(G32="●",B32*C32,0)+IF(G33="●",B33*C33,0)+IF(G34="●",B34*C34,0) | H35: =IF(H30="●",B30*C30,0)+IF(H31="●",B31*C31,0)+IF(H32="●",B32*C32,0)+IF(H33="●",B33*C33,0)+IF(H34="●",B34*C34,0) | I35: =IF(I30="●",B30*C30,0)+IF(I31="●",B31*C31,0)+IF(I32="●",B32*C32,0)+IF(I33="●",B33*C33,0)+IF(I34="●",B34*C34,0) | J35: =SUM(J30:J34) | K35: =SUM(K30:K34) | L35: =IF(L30="●",B30*C30,0)+IF(L31="●",B31*C31,0)+IF(L32="●",B32*C32,0)+IF(L33="●",B33*C33,0)+IF(L34="●",B34*C34,0) | M35: =IF(M30="●",B30*C30,0)+IF(M31="●",B31*C31,0)+IF(M32="●",B32*C32,0)+IF(M33="●",B33*C33,0)+IF(M34="●",B34*C34,0) | N35: =IF(N30="●",B30*C30,0)+IF(N31="●",B31*C31,0)+IF(N32="●",B32*C32,0)+IF(N33="●",B33*C33,0)+IF(N34="●",B34*C34,0) | O35: =IF(O30="●",B30*C30,0)+IF(O31="●",B31*C31,0)+IF(O32="●",B32*C32,0)+IF(O33="●",B33*C33,0)+IF(O34="●",B34*C34,0)
A37: 📦 OTHER
A38: Insurance / Tips / Contingency | B38: 4 | C38: =IF(A38="","",VLOOKUP(A38,'Master Data'!$A$50:$C$56,2,FALSE)) | D38: =IF(A38="","",VLOOKUP(A38,'Master Data'!$A$50:$C$56,3,FALSE)) | E38: =IF(D38>0,(D38-C38)/D38,0) | J38: =IF(A38="","",IF(OR((F38="●")+(G38="●")+(H38="●")+(I38="●")+(L38="●")+(M38="●")+(N38="●")+(O38="●")),B38*C38,0)) | K38: =IF(A38="","",IF(OR((F38="●")+(G38="●")+(H38="●")+(I38="●")+(L38="●")+(M38="●")+(N38="●")+(O38="●")),B38*D38,0)) | Q38: =0 | R38: pg
C39: =IF(A39="","",VLOOKUP(A39,'Master Data'!$A$50:$C$56,2,FALSE)) | D39: =IF(A39="","",VLOOKUP(A39,'Master Data'!$A$50:$C$56,3,FALSE)) | E39: =IF(D39>0,(D39-C39)/D39,0) | J39: =IF(A39="","",(COUNTIF(F39,"●")+COUNTIF(G39,"●")+COUNTIF(H39,"●")+COUNTIF(I39,"●")+COUNTIF(L39,"●")+COUNTIF(M39,"●")+COUNTIF(N39,"●")+COUNTIF(O39,"●"))*B39*C39) | K39: =IF(A39="","",(COUNTIF(F39,"●")+COUNTIF(G39,"●")+COUNTIF(H39,"●")+COUNTIF(I39,"●")+COUNTIF(L39,"●")+COUNTIF(M39,"●")+COUNTIF(N39,"●")+COUNTIF(O39,"●"))*B39*D39) | Q39: =IF(A39="",0,COUNTIF(A$38:A38,A39))
C40: =IF(A40="","",VLOOKUP(A40,'Master Data'!$A$50:$C$56,2,FALSE)) | D40: =IF(A40="","",VLOOKUP(A40,'Master Data'!$A$50:$C$56,3,FALSE)) | E40: =IF(D40>0,(D40-C40)/D40,0) | J40: =IF(A40="","",(COUNTIF(F40,"●")+COUNTIF(G40,"●")+COUNTIF(H40,"●")+COUNTIF(I40,"●")+COUNTIF(L40,"●")+COUNTIF(M40,"●")+COUNTIF(N40,"●")+COUNTIF(O40,"●"))*B40*C40) | K40: =IF(A40="","",(COUNTIF(F40,"●")+COUNTIF(G40,"●")+COUNTIF(H40,"●")+COUNTIF(I40,"●")+COUNTIF(L40,"●")+COUNTIF(M40,"●")+COUNTIF(N40,"●")+COUNTIF(O40,"●"))*B40*D40) | Q40: =IF(A40="",0,COUNTIF(A$38:A39,A40))
A41: SUBTOTAL | F41: =IF(OR(F38="●"),B38*C38,0)+IF(F39="●",B39*C39,0)+IF(F40="●",B40*C40,0) | G41: =IF(OR(G38="●"),B38*C38,0)+IF(G39="●",B39*C39,0)+IF(G40="●",B40*C40,0) | H41: =IF(OR(H38="●"),B38*C38,0)+IF(H39="●",B39*C39,0)+IF(H40="●",B40*C40,0) | I41: =IF(OR(I38="●"),B38*C38,0)+IF(I39="●",B39*C39,0)+IF(I40="●",B40*C40,0) | J41: =SUM(J38:J40) | K41: =SUM(K38:K40) | L41: =IF(OR(L38="●"),B38*C38,0)+IF(L39="●",B39*C39,0)+IF(L40="●",B40*C40,0) | M41: =IF(OR(M38="●"),B38*C38,0)+IF(M39="●",B39*C39,0)+IF(M40="●",B40*C40,0) | N41: =IF(OR(N38="●"),B38*C38,0)+IF(N39="●",B39*C39,0)+IF(N40="●",B40*C40,0) | O41: =IF(OR(O38="●"),B38*C38,0)+IF(O39="●",B39*C39,0)+IF(O40="●",B40*C40,0)
A43: 🎯 ACTIVITIES
A44: Beach/Surf Lesson | B44: 1 | C44: =IF(A44="","",VLOOKUP(A44,'Master Data'!$A$86:$C$94,2,FALSE)) | D44: =IF(A44="","",VLOOKUP(A44,'Master Data'!$A$86:$C$94,3,FALSE)) | E44: =IF(D44>0,(D44-C44)/D44,0) | J44: =IF(A44="","",(COUNTIF(F44,"●")+COUNTIF(G44,"●")+COUNTIF(H44,"●")+COUNTIF(I44,"●")+COUNTIF(L44,"●")+COUNTIF(M44,"●")+COUNTIF(N44,"●")+COUNTIF(O44,"●"))*B44*C44) | K44: =IF(A44="","",(COUNTIF(F44,"●")+COUNTIF(G44,"●")+COUNTIF(H44,"●")+COUNTIF(I44,"●")+COUNTIF(L44,"●")+COUNTIF(M44,"●")+COUNTIF(N44,"●")+COUNTIF(O44,"●"))*B44*D44) | Q44: =0 | R44: pp
A45: Local Hiking (Griffith/Runyon) | B45: 1 | C45: =IF(A45="","",VLOOKUP(A45,'Master Data'!$A$86:$C$94,2,FALSE)) | D45: =IF(A45="","",VLOOKUP(A45,'Master Data'!$A$86:$C$94,3,FALSE)) | E45: =IF(D45>0,(D45-C45)/D45,0) | J45: =IF(A45="","",(COUNTIF(F45,"●")+COUNTIF(G45,"●")+COUNTIF(H45,"●")+COUNTIF(I45,"●")+COUNTIF(L45,"●")+COUNTIF(M45,"●")+COUNTIF(N45,"●")+COUNTIF(O45,"●"))*B45*C45) | K45: =IF(A45="","",(COUNTIF(F45,"●")+COUNTIF(G45,"●")+COUNTIF(H45,"●")+COUNTIF(I45,"●")+COUNTIF(L45,"●")+COUNTIF(M45,"●")+COUNTIF(N45,"●")+COUNTIF(O45,"●"))*B45*D45) | Q45: =IF(A45="",0,COUNTIF(A$44:A44,A45)) | R45: pp
...

Sheet Package Summary
A1: 📊 PACKAGE SUMMARY
A4: Category | B4: Total Cost | C4: Total Sell | D4: Margin | E4: Margin% | F4: Per Person
A5: GOLF | B5: ='Package Selector'!J15 | C5: ='Package Selector'!K15 | D5: =C5-B5 | E5: =IF(C5>0,D5/C5,0) | F5: =IF(E2>0,B5/E2,0)
A6: HOTEL | B6: ='Package Selector'!J21 | C6: ='Package Selector'!K21 | D6: =C6-B6 | E6: =IF(C6>0,D6/C6,0) | F6: =IF(E2>0,B6/E2,0)
A7: TRANSPORT | B7: ='Package Selector'!J27 | C7: ='Package Selector'!K27 | D7: =C7-B7 | E7: =IF(C7>0,D7/C7,0) | F7: =IF(E2>0,B7/E2,0)
A8: MEALS | B8: ='Package Selector'!J35 | C8: ='Package Selector'!K35 | D8: =C8-B8 | E8: =IF(C8>0,D8/C8,0) | F8: =IF(E2>0,B8/E2,0)
A9: OTHER | B9: ='Package Selector'!J41 | C9: ='Package Selector'!K41 | D9: =C9-B9 | E9: =IF(C9>0,D9/C9,0) | F9: =IF(E2>0,B9/E2,0)
A10: ACTIVITIES | B10: ='Package Selector'!J53 | C10: ='Package Selector'!K53 | D10: =C10-B10 | E10: =IF(C10>0,D10/C10,0) | F10: =IF(E2>0,B10/E2,0)
A11: 📌 TOTAL | B11: =SUM(B5:B10) | C11: =SUM(C5:C10) | D11: =SUM(D5:D10)

Sheet Guest Package
A1: 🎫 GUEST PACKAGE
A3: Package: | B3: ='Package Selector'!B2
A4: Guests: | B4: ='Package Selector'!E2
A5: Duration: | B5: ='Package Selector'!J6
A7: ⛳ Golf | B7: =TEXTJOIN(", ",TRUE,IF((COUNTIF(F9:I14,"●")+COUNTIF(L9:O14,"●"))>0,A9:A14,""))
A8: 🏨 Hotel | B8: =TEXTJOIN(", ",TRUE,IF((COUNTIF(F17:I21,"●")+COUNTIF(L17:O21,"●"))>0,A17:A21,""))
A9: 🚐 Transport | B9: =TEXTJOIN(", ",TRUE,IF((COUNTIF(F23:I27,"●")+COUNTIF(L23:O27,"●"))>0,A23:A27,""))
A10: 🍽️ Meals | B10: =TEXTJOIN(", ",TRUE,IF((COUNTIF(F29:I35,"●")+COUNTIF(L29:O35,"●"))>0,A29:A35,""))
A11: 📦 Other | B11: =TEXTJOIN(", ",TRUE,IF((COUNTIF(F37:I41,"●")+COUNTIF(L37:O41,"●"))>0,A37:A41,""))
A12: 🎯 Activities | B12: =TEXTJOIN(", ",TRUE,IF((COUNTIF(F43:I53,"●")+COUNTIF(L43:O53,"●"))>0,A43:A53,""))
A14: 💰 ALL-INCLUSIVE PRICE
A15: Total: | B15: ='Package Selector'!K72
