Workbook

Sheet Master Data
A1: MASTER DATA - Yellow=input Blue=auto | Mode: Margin%->Sell or Sell->Margin%
A2: Margin%->Sell: input margin -> auto sell | Sell->Margin%: input sell -> auto margin% | 2026-05-20
A4: GOLF COURSES (per person per round, USD)
A5: Name | B5: Mode | C5: Cost | D5: Margin% | E5: Sell | F5: Margin | G5: Notes
A6: Trump National LA | B6: Margin%->Sell | C6: 210 | D6: 1.381 | E6: =IF(B6="Margin%->Sell",C6*(1+D6),C6) | F6: =E6-C6 | G6: Member guest | Cart incl
A7: Sandpiper GC | B7: Margin%->Sell | C7: 130 | D7: 0.885 | E7: =IF(B7="Margin%->Sell",C7*(1+D7),C7) | F7: =E7-C7 | G7: UnderPar.com | Replay free
A8: Hidden Valley GC | B8: Sell->Margin% | C8: 109 | D8: =IF(AND(B8="Sell->Margin%",C8>0),(E8-C8)/C8,0) | E8: 109 | F8: =E8-C8 | G8: Weekend Prime | 9Stamp=1free
A10: + Add (input in yellow cells)
A11: New 1 | B11: Margin%->Sell | D11: =IF(AND(B11="Sell->Margin%",C11>0),(E11-C11)/C11,"") | E11: =IF(B11="Margin%->Sell",IF(C11>0,C11*(1+D11),""),E11) | F11: =IF(AND(C11>0,E11>0),E11-C11,"")
A12: New 2 | B12: Margin%->Sell | D12: =IF(AND(B12="Sell->Margin%",C12>0),(E12-C12)/C12,"") | E12: =IF(B12="Margin%->Sell",IF(C12>0,C12*(1+D12),""),E12) | F12: =IF(AND(C12>0,E12>0),E12-C12,"")
A13: New 3 | B13: Margin%->Sell | D13: =IF(AND(B13="Sell->Margin%",C13>0),(E13-C13)/C13,"") | E13: =IF(B13="Margin%->Sell",IF(C13>0,C13*(1+D13),""),E13) | F13: =IF(AND(C13>0,E13>0),E13-C13,"")
A15: HOTELS (per person per night, Double Occ.)
A16: Name | B16: Mode | C16: Cost | D16: Margin% | E16: Sell | F16: Margin | G16: Notes
A17: Beverly Wilshire (5*) | B17: Margin%->Sell | C17: 275 | D17: 0.364 | E17: =IF(B17="Margin%->Sell",C17*(1+D17),C17) | F17: =E17-C17 | G17: $550/room / 2
A19: + Add (input in yellow cells)
A20: New 1 | B20: Margin%->Sell | D20: =IF(AND(B20="Sell->Margin%",C20>0),(E20-C20)/C20,"") | E20: =IF(B20="Margin%->Sell",IF(C20>0,C20*(1+D20),""),E20) | F20: =IF(AND(C20>0,E20>0),E20-C20,"")
A21: New 2 | B21: Margin%->Sell | D21: =IF(AND(B21="Sell->Margin%",C21>0),(E21-C21)/C21,"") | E21: =IF(B21="Margin%->Sell",IF(C21>0,C21*(1+D21),""),E21) | F21: =IF(AND(C21>0,E21>0),E21-C21,"")
A23: TRANSPORT (per person, 4pax/group)
A24: Name | B24: Mode | C24: Cost | D24: Margin% | E24: Sell | F24: Margin | G24: Notes
A25: Driver+Guide+Van (daily) | B25: Margin%->Sell | C25: 125 | D25: 0.4 | E25: =IF(B25="Margin%->Sell",C25*(1+D25),C25) | F25: =E25-C25 | G25: $500/day / 4
A26: Airport RT pickup | B26: Margin%->Sell | C26: 75 | D26: 0.6 | E26: =IF(B26="Margin%->Sell",C26*(1+D26),C26) | F26: =E26-C26 | G26: LAX<->Hotel
A28: + Add (input in yellow cells)
A29: New 1 | B29: Margin%->Sell | D29: =IF(AND(B29="Sell->Margin%",C29>0),(E29-C29)/C29,"") | E29: =IF(B29="Margin%->Sell",IF(C29>0,C29*(1+D29),""),E29) | F29: =IF(AND(C29>0,E29>0),E29-C29,"")
A30: New 2 | B30: Margin%->Sell | D30: =IF(AND(B30="Sell->Margin%",C30>0),(E30-C30)/C30,"") | E30: =IF(B30="Margin%->Sell",IF(C30>0,C30*(1+D30),""),E30) | F30: =IF(AND(C30>0,E30>0),E30-C30,"")
A32: MEALS (per person per meal)
A33: Name | B33: Mode | C33: Cost | D33: Margin% | E33: Sell | F33: Margin | G33: Notes
A34: Breakfast (hotel) | B34: Margin%->Sell | C34: 30 | D34: 0.5 | E34: =IF(B34="Margin%->Sell",C34*(1+D34),C34) | F34: =E34-C34 | G34: Daily
A35: Lunch | B35: Margin%->Sell | C35: 40 | D35: 0.5 | E35: =IF(B35="Margin%->Sell",C35*(1+D35),C35) | F35: =E35-C35 | G35: Daily
A36: Dinner (standard) | B36: Margin%->Sell | C36: 80 | D36: 0.5 | E36: =IF(B36="Margin%->Sell",C36*(1+D36),C36) | F36: =E36-C36 | G36: Standard
A37: Exclusive Dinner | B37: Margin%->Sell | C37: 120 | D37: 0.5 | E37: =IF(B37="Margin%->Sell",C37*(1+D37),C37) | F37: =E37-C37 | G37: 2x per trip
A39: + Add (input in yellow cells)
A40: New 1 | B40: Margin%->Sell | D40: =IF(AND(B40="Sell->Margin%",C40>0),(E40-C40)/C40,"") | E40: =IF(B40="Margin%->Sell",IF(C40>0,C40*(1+D40),""),E40) | F40: =IF(AND(C40>0,E40>0),E40-C40,"")
A41: New 2 | B41: Margin%->Sell | D41: =IF(AND(B41="Sell->Margin%",C41>0),(E41-C41)/C41,"") | E41: =IF(B41="Margin%->Sell",IF(C41>0,C41*(1+D41),""),E41) | F41: =IF(AND(C41>0,E41>0),E41-C41,"")
A43: OTHER (per person per day)
A44: Name | B44: Mode | C44: Cost | D44: Margin% | E44: Sell | F44: Margin | G44: Notes
A45: Misc (insurance,tips) | B45: Margin%->Sell | C45: 50 | D45: 0.5 | E45: =IF(B45="Margin%->Sell",C45*(1+D45),C45) | F45: =E45-C45 | G45: Daily
A47: + Add (input in yellow cells)
A48: New 1 | B48: Margin%->Sell | D48: =IF(AND(B48="Sell->Margin%",C48>0),(E48-C48)/C48,"") | E48: =IF(B48="Margin%->Sell",IF(C48>0,C48*(1+D48),""),E48) | F48: =IF(AND(C48>0,E48>0),E48-C48,"")
A49: New 2 | B49: Margin%->Sell | D49: =IF(AND(B49="Sell->Margin%",C49>0),(E49-C49)/C49,"") | E49: =IF(B49="Margin%->Sell",IF(C49>0,C49*(1+D49),""),E49) | F49: =IF(AND(C49>0,E49>0),E49-C49,"")

Sheet Package Builder
A1: PACKAGE BUILDER - Dropdown+Manual->Auto Quote
A2: Yellow=input Blue=auto | Mode: Margin%<->Sell
A4: PACKAGE INFO (dropdowns)
A5: Package Name | C5: New Package
A6: Duration | C6: 3N4D | F6: Golfers | H6: 2
A7: Hotel Nights (auto) | C7: =IF(C6="3N4D",3,IF(C6="4N5D",4,IF(C6="5N6D",5,IF(C6="6N7D",6,IF(C6="7N8D",7,IF(C6="10N11D",10,IF(C6="12N13D",12,3))))))) | F7: Travel Days (auto) | H7: =C7+1
A9: GOLF ROUNDS (dropdown course + mode + rounds)
A10: # | B10: Mode | C10: Course | D10: Rounds | E10: Cost/rd | F10: Margin% | G10: Sell/rd | H10: TotCost | I10: TotSell | J10: Margin
A11: 1 | B11: Margin%->Sell | C11: Trump National LA | D11: 2 | E11: =IF(C11="","",VLOOKUP(C11,Master Data!$A$6:$C$18,3,FALSE)) | F11: =IF(C11="","",IF(B11="Sell->Margin%",IF(E11>0,(G11-E11)/E11,0),VLOOKUP(C11,Master Data!$A$6:$D$18,4,FALSE))) | G11: =IF(C11="","",IF(B11="Margin%->Sell",E11*(1+F11),VLOOKUP(C11,Master Data!$A$6:$E$18,5,FALSE))) | H11: =IF(AND(C11<>"",D11>0),D11*E11,"") | I11: =IF(AND(C11<>"",D11>0),D11*G11,"") | J11: =IF(I11<>"",I11-H11,"")
A12: 2 | B12: Margin%->Sell | C12: Sandpiper GC | D12: 2 | E12: =IF(C12="","",VLOOKUP(C12,Master Data!$A$6:$C$18,3,FALSE)) | F12: =IF(C12="","",IF(B12="Sell->Margin%",IF(E12>0,(G12-E12)/E12,0),VLOOKUP(C12,Master Data!$A$6:$D$18,4,FALSE))) | G12: =IF(C12="","",IF(B12="Margin%->Sell",E12*(1+F12),VLOOKUP(C12,Master Data!$A$6:$E$18,5,FALSE))) | H12: =IF(AND(C12<>"",D12>0),D12*E12,"") | I12: =IF(AND(C12<>"",D12>0),D12*G12,"") | J12: =IF(I12<>"",I12-H12,"")
A13: 3 | B13: Sell->Margin% | C13: Hidden Valley GC | D13: 1 | E13: =IF(C13="","",VLOOKUP(C13,Master Data!$A$6:$C$18,3,FALSE)) | F13: =IF(C13="","",IF(B13="Sell->Margin%",IF(E13>0,(G13-E13)/E13,0),VLOOKUP(C13,Master Data!$A$6:$D$18,4,FALSE))) | G13: =IF(C13="","",IF(B13="Margin%->Sell",E13*(1+F13),VLOOKUP(C13,Master Data!$A$6:$E$18,5,FALSE))) | H13: =IF(AND(C13<>"",D13>0),D13*E13,"") | I13: =IF(AND(C13<>"",D13>0),D13*G13,"") | J13: =IF(I13<>"",I13-H13,"")
B14: Margin%->Sell | E14: =IF(C14="","",VLOOKUP(C14,Master Data!$A$6:$C$18,3,FALSE)) | F14: =IF(C14="","",IF(B14="Sell->Margin%",IF(E14>0,(G14-E14)/E14,0),VLOOKUP(C14,Master Data!$A$6:$D$18,4,FALSE))) | G14: =IF(C14="","",IF(B14="Margin%->Sell",E14*(1+F14),VLOOKUP(C14,Master Data!$A$6:$E$18,5,FALSE))) | H14: =IF(AND(C14<>"",D14>0),D14*E14,"") | I14: =IF(AND(C14<>"",D14>0),D14*G14,"") | J14: =IF(I14<>"",I14-H14,"")
B15: Margin%->Sell | E15: =IF(C15="","",VLOOKUP(C15,Master Data!$A$6:$C$18,3,FALSE)) | F15: =IF(C15="","",IF(B15="Sell->Margin%",IF(E15>0,(G15-E15)/E15,0),VLOOKUP(C15,Master Data!$A$6:$D$18,4,FALSE))) | G15: =IF(C15="","",IF(B15="Margin%->Sell",E15*(1+F15),VLOOKUP(C15,Master Data!$A$6:$E$18,5,FALSE))) | H15: =IF(AND(C15<>"",D15>0),D15*E15,"") | I15: =IF(AND(C15<>"",D15>0),D15*G15,"") | J15: =IF(I15<>"",I15-H15,"")
B16: Margin%->Sell | E16: =IF(C16="","",VLOOKUP(C16,Master Data!$A$6:$C$18,3,FALSE)) | F16: =IF(C16="","",IF(B16="Sell->Margin%",IF(E16>0,(G16-E16)/E16,0),VLOOKUP(C16,Master Data!$A$6:$D$18,4,FALSE))) | G16: =IF(C16="","",IF(B16="Margin%->Sell",E16*(1+F16),VLOOKUP(C16,Master Data!$A$6:$E$18,5,FALSE))) | H16: =IF(AND(C16<>"",D16>0),D16*E16,"") | I16: =IF(AND(C16<>"",D16>0),D16*G16,"") | J16: =IF(I16<>"",I16-H16,"")
A17: GOLF SUBTOTAL | H17: =SUM(H11:H16) | I17: =SUM(I11:I16) | J17: =SUM(J11:J16)
A19: HOTEL (nights auto from package info)
A20: # | B20: Mode | C20: Hotel | D20: Nights | E20: Cost/nt | F20: Margin% | G20: Sell/nt | H20: TotCost | I20: TotSell | J20: Margin
A21: 1 | B21: Margin%->Sell | C21: Beverly Wilshire (5*) | D21: =$C$7 | E21: =IF(C21="","",VLOOKUP(C21,Master Data!$A$17:$C$27,3,FALSE)) | F21: =IF(C21="","",IF(B21="Sell->Margin%",IF(E21>0,(G21-E21)/E21,0),VLOOKUP(C21,Master Data!$A$17:$D$27,4,FALSE))) | G21: =IF(C21="","",IF(B21="Margin%->Sell",E21*(1+F21),VLOOKUP(C21,Master Data!$A$17:$E$27,5,FALSE))) | H21: =IF(AND(C21<>"",D21>0),D21*E21,"") | I21: =IF(AND(C21<>"",D21>0),D21*G21,"") | J21: =IF(I21<>"",I21-H21,"")
B22: Margin%->Sell | E22: =IF(C22="","",VLOOKUP(C22,Master Data!$A$17:$C$27,3,FALSE)) | F22: =IF(C22="","",IF(B22="Sell->Margin%",IF(E22>0,(G22-E22)/E22,0),VLOOKUP(C22,Master Data!$A$17:$D$27,4,FALSE))) | G22: =IF(C22="","",IF(B22="Margin%->Sell",E22*(1+F22),VLOOKUP(C22,Master Data!$A$17:$E$27,5,FALSE))) | H22: =IF(AND(C22<>"",D22>0),D22*E22,"") | I22: =IF(AND(C22<>"",D22>0),D22*G22,"") | J22: =IF(I22<>"",I22-H22,"")
B23: Margin%->Sell | E23: =IF(C23="","",VLOOKUP(C23,Master Data!$A$17:$C$27,3,FALSE)) | F23: =IF(C23="","",IF(B23="Sell->Margin%",IF(E23>0,(G23-E23)/E23,0),VLOOKUP(C23,Master Data!$A$17:$D$27,4,FALSE))) | G23: =IF(C23="","",IF(B23="Margin%->Sell",E23*(1+F23),VLOOKUP(C23,Master Data!$A$17:$E$27,5,FALSE))) | H23: =IF(AND(C23<>"",D23>0),D23*E23,"") | I23: =IF(AND(C23<>"",D23>0),D23*G23,"") | J23: =IF(I23<>"",I23-H23,"")
A24: HOTEL SUBTOTAL | H24: =SUM(H21:H23) | I24: =SUM(I21:I23) | J24: =SUM(J21:J23)
A26: TRANSPORT (travel days auto)
A27: # | B27: Mode | C27: Item | D27: Days | E27: Cost/day | F27: Margin% | G27: Sell/day | H27: TotCost | I27: TotSell | J27: Margin
A28: 1 | B28: Margin%->Sell | C28: Driver+Guide+Van (daily) | D28: =$C$8 | E28: =IF(C28="","",VLOOKUP(C28,Master Data!$A$25:$C$36,3,FALSE)) | F28: =IF(C28="","",IF(B28="Sell->Margin%",IF(E28>0,(G28-E28)/E28,0),VLOOKUP(C28,Master Data!$A$25:$D$36,4,FALSE))) | G28: =IF(C28="","",IF(B28="Margin%->Sell",E28*(1+F28),VLOOKUP(C28,Master Data!$A$25:$E$36,5,FALSE))) | H28: =IF(AND(C28<>"",D28>0),D28*E28,"") | I28: =IF(AND(C28<>"",D28>0),D28*G28,"") | J28: =IF(I28<>"",I28-H28,"")
A29: 2 | B29: Margin%->Sell | C29: Airport RT pickup | D29: 2 | E29: =IF(C29="","",VLOOKUP(C29,Master Data!$A$25:$C$36,3,FALSE)) | F29: =IF(C29="","",IF(B29="Sell->Margin%",IF(E29>0,(G29-E29)/E29,0),VLOOKUP(C29,Master Data!$A$25:$D$36,4,FALSE))) | G29: =IF(C29="","",IF(B29="Margin%->Sell",E29*(1+F29),VLOOKUP(C29,Master Data!$A$25:$E$36,5,FALSE))) | H29: =IF(AND(C29<>"",D29>0),D29*E29,"") | I29: =IF(AND(C29<>"",D29>0),D29*G29,"") | J29: =IF(I29<>"",I29-H29,"")
B30: Margin%->Sell | E30: =IF(C30="","",VLOOKUP(C30,Master Data!$A$25:$C$36,3,FALSE)) | F30: =IF(C30="","",IF(B30="Sell->Margin%",IF(E30>0,(G30-E30)/E30,0),VLOOKUP(C30,Master Data!$A$25:$D$36,4,FALSE))) | G30: =IF(C30="","",IF(B30="Margin%->Sell",E30*(1+F30),VLOOKUP(C30,Master Data!$A$25:$E$36,5,FALSE))) | H30: =IF(AND(C30<>"",D30>0),D30*E30,"") | I30: =IF(AND(C30<>"",D30>0),D30*G30,"") | J30: =IF(I30<>"",I30-H30,"")
B31: Margin%->Sell | E31: =IF(C31="","",VLOOKUP(C31,Master Data!$A$25:$C$36,3,FALSE)) | F31: =IF(C31="","",IF(B31="Sell->Margin%",IF(E31>0,(G31-E31)/E31,0),VLOOKUP(C31,Master Data!$A$25:$D$36,4,FALSE))) | G31: =IF(C31="","",IF(B31="Margin%->Sell",E31*(1+F31),VLOOKUP(C31,Master Data!$A$25:$E$36,5,FALSE))) | H31: =IF(AND(C31<>"",D31>0),D31*E31,"") | I31: =IF(AND(C31<>"",D31>0),D31*G31,"") | J31: =IF(I31<>"",I31-H31,"")
A32: TRANSPORT SUBTOTAL | H32: =SUM(H28:H31) | I32: =SUM(I28:I31) | J32: =SUM(J28:J31)
A34: MEALS and OTHER
A35: # | B35: Mode | C35: Item | D35: Qty | E35: Cost/unit | F35: Margin% | G35: Sell/unit | H35: TotCost | I35: TotSell | J35: Margin
A36: 1 | B36: Margin%->Sell | C36: Meal Package (3 meals) | D36: =$C$7 | E36: 150 | F36: 0.5 | G36: =IF(AND(C36<>"",E36<>""),IF(B36="Margin%->Sell",E36*(1+F36),G36),"") | H36: =IF(AND(C36<>"",D36>0,E36<>""),D36*E36,"") | I36: =IF(AND(C36<>"",D36>0,G36<>""),D36*G36,"") | J36: =IF(I36<>"",I36-H36,"")
A37: 2 | B37: Margin%->Sell | C37: Misc (insurance,tips) | D37: =$C$8 | E37: 50 | F37: 0.5 | G37: =IF(AND(C37<>"",E37<>""),IF(B37="Margin%->Sell",E37*(1+F37),G37),"") | H37: =IF(AND(C37<>"",D37>0,E37<>""),D37*E37,"") | I37: =IF(AND(C37<>"",D37>0,G37<>""),D37*G37,"") | J37: =IF(I37<>"",I37-H37,"")
B38: Margin%->Sell | G38: =IF(AND(C38<>"",E38<>""),IF(B38="Margin%->Sell",E38*(1+F38),G38),"") | H38: =IF(AND(C38<>"",D38>0,E38<>""),D38*E38,"") | I38: =IF(AND(C38<>"",D38>0,G38<>""),D38*G38,"") | J38: =IF(I38<>"",I38-H38,"")
B39: Margin%->Sell | G39: =IF(AND(C39<>"",E39<>""),IF(B39="Margin%->Sell",E39*(1+F39),G39),"") | H39: =IF(AND(C39<>"",D39>0,E39<>""),D39*E39,"") | I39: =IF(AND(C39<>"",D39>0,G39<>""),D39*G39,"") | J39: =IF(I39<>"",I39-H39,"")
B40: Margin%->Sell | G40: =IF(AND(C40<>"",E40<>""),IF(B40="Margin%->Sell",E40*(1+F40),G40),"") | H40: =IF(AND(C40<>"",D40>0,E40<>""),D40*E40,"") | I40: =IF(AND(C40<>"",D40>0,G40<>""),D40*G40,"") | J40: =IF(I40<>"",I40-H40,"")
A41: MEALS+OTHER SUBTOTAL | H41: =SUM(H36:H40) | I41: =SUM(I36:I40) | J41: =SUM(J36:J40)
A43: GRAND TOTAL
B44: Total Cost | C44: Total Sell | D44: Total Margin | E44: Margin% | F44: Per Person
A45: GOLF | B45: =H17 | C45: =I17 | D45: =J17 | E45: =IF(C45>0,D45/C45,"") | F45: =IF($C$8>0,C45/$C$8,"")
A46: HOTEL | B46: =H24 | C46: =I24 | D46: =J24 | E46: =IF(C46>0,D46/C46,"") | F46: =IF($C$8>0,C46/$C$8,"")
...

Sheet Profit Summary
A1: PROFIT SUMMARY - Auto-linked to Package Builder
A2: Changes in Package Builder auto-reflect here
A4: Item | B4: Total Cost | C4: Total Sell | D4: Total Margin | E4: Margin% | F4: Per Person | G4: Per Person Margin
A5: GOLF | B5: ='Package Builder'!H17 | C5: ='Package Builder'!I17 | D5: ='Package Builder'!J17 | E5: =IF(C5>0,D5/C5,"") | F5: =IF('Package Builder'!$C$8>0,C5/'Package Builder'!$C$8,"") | G5: =IF('Package Builder'!$C$8>0,D5/'Package Builder'!$C$8,"")
A6: HOTEL | B6: ='Package Builder'!H24 | C6: ='Package Builder'!I24 | D6: ='Package Builder'!J24 | E6: =IF(C6>0,D6/C6,"") | F6: =IF('Package Builder'!$C$8>0,C6/'Package Builder'!$C$8,"") | G6: =IF('Package Builder'!$C$8>0,D6/'Package Builder'!$C$8,"")
A7: TRANSPORT | B7: ='Package Builder'!H32 | C7: ='Package Builder'!I32 | D7: ='Package Builder'!J32 | E7: =IF(C7>0,D7/C7,"") | F7: =IF('Package Builder'!$C$8>0,C7/'Package Builder'!$C$8,"") | G7: =IF('Package Builder'!$C$8>0,D7/'Package Builder'!$C$8,"")
A8: MEALS+OTHER | B8: ='Package Builder'!H41 | C8: ='Package Builder'!I41 | D8: ='Package Builder'!J41 | E8: =IF(C8>0,D8/C8,"") | F8: =IF('Package Builder'!$C$8>0,C8/'Package Builder'!$C$8,"") | G8: =IF('Package Builder'!$C$8>0,D8/'Package Builder'!$C$8,"")
A10: GRAND TOTAL
A11: Total Cost | B11: =SUM(B5:B9)
A12: Overall Margin% | B12: =IF(C11>0,D11/C11,"") | C12: =SUM(C5:C9) | D12: Per Person Total Sell | E12: =IF('Package Builder'!$C$8>0,C11/'Package Builder'!$C$8,"")
D13: =SUM(D5:D9)
